Traceback (most recent call last):
  File "GitHub/Rest_and_RPC_research/tasks/python/rest/client.py", line 5, in <module>
    response = requests.get(url)
  File "/usr/lib/python2.7/dist-packages/requests/api.py", line 70, in get
    return request('get', url, params=params, **kwargs)
  File "/usr/lib/python2.7/dist-packages/requests/api.py", line 56, in request
    return session.request(method=method, url=url, **kwargs)
  File "/usr/lib/python2.7/dist-packages/requests/sessions.py", line 488, in request
    resp = self.send(prep, **send_kwargs)
  File "/usr/lib/python2.7/dist-packages/requests/sessions.py", line 609, in send
    r = adapter.send(request, **kwargs)
  File "/usr/lib/python2.7/dist-packages/requests/adapters.py", line 487, in send
    raise ConnectionError(e, request=request)
requests.exceptions.ConnectionError: HTTPConnectionPool(host='195.251.251.27', port=8080): Max retries exceeded with url: / (Caused by NewConnectionError('<requests.packages.urllib3.connection.HTTPConnection object at 0x760c5050>: Failed to establish a new connection: [Errno 111] Connection refused',))

real	0m1.859s
user	0m1.773s
sys	0m0.070s
