+ strace -f -e trace=network -c python ../tasks//python/grpc/server.py
strace: Process 16332 attached
strace: Process 16333 attached
strace: Process 16334 attached
E0518 17:43:54.971255783   16329 server_chttp2.cc:40]        {"created":"@1526654634.971218077","description":"No address added out of total 1 resolved","file":"src/core/ext/transport/chttp2/server/chttp2_server.cc","file_line":307,"referenced_errors":[{"created":"@1526654634.971207998","description":"Failed to add any wildcard listeners","file":"src/core/lib/iomgr/tcp_server_posix.cc","file_line":345,"referenced_errors":[{"created":"@1526654634.971068635","description":"Unable to configure socket","fd":6,"file":"src/core/lib/iomgr/tcp_server_utils_posix_common.cc","file_line":202,"referenced_errors":[{"created":"@1526654634.971048590","description":"OS Error","errno":98,"file":"src/core/lib/iomgr/tcp_server_utils_posix_common.cc","file_line":175,"os_error":"Address already in use","syscall":"bind"}]},{"created":"@1526654634.971198812","description":"Unable to configure socket","fd":6,"file":"src/core/lib/iomgr/tcp_server_utils_posix_common.cc","file_line":202,"referenced_errors":[{"created":"@1526654634.971179596","description":"OS Error","errno":98,"file":"src/core/lib/iomgr/tcp_server_utils_posix_common.cc","file_line":175,"os_error":"Address already in use","syscall":"bind"}]}]}]}
strace: Process 16335 attached
