Traceback (most recent call last):
  File "/usr/local/lib/python3.6/urllib/request.py", line 1318, in do_open
    encode_chunked=req.has_header('Transfer-encoding'))
  File "/usr/local/lib/python3.6/http/client.py", line 1239, in request
    self._send_request(method, url, body, headers, encode_chunked)
  File "/usr/local/lib/python3.6/http/client.py", line 1285, in _send_request
    self.endheaders(body, encode_chunked=encode_chunked)
  File "/usr/local/lib/python3.6/http/client.py", line 1234, in endheaders
    self._send_output(message_body, encode_chunked=encode_chunked)
  File "/usr/local/lib/python3.6/http/client.py", line 1026, in _send_output
    self.send(msg)
  File "/usr/local/lib/python3.6/http/client.py", line 964, in send
    self.connect()
  File "/usr/local/lib/python3.6/http/client.py", line 936, in connect
    (self.host,self.port), self.timeout, self.source_address)
  File "/usr/local/lib/python3.6/socket.py", line 724, in create_connection
    raise err
  File "/usr/local/lib/python3.6/socket.py", line 713, in create_connection
    sock.connect(sa)
ConnectionRefusedError: [Errno 111] Connection refused

During handling of the above exception, another exception occurred:

Traceback (most recent call last):
  File "GitHub/Rest_and_RPC_research/tasks/python/rpc/client.py", line 6, in <module>
    server.App.index('Stefanos')
  File "/usr/local/lib/python3.6/site-packages/flask_jsonrpc/proxy.py", line 78, in __call__
    r = self.send_payload(params)
  File "/usr/local/lib/python3.6/site-packages/flask_jsonrpc/proxy.py", line 70, in send_payload
    return urlopen(url_request).read()
  File "/usr/local/lib/python3.6/urllib/request.py", line 223, in urlopen
    return opener.open(url, data, timeout)
  File "/usr/local/lib/python3.6/urllib/request.py", line 526, in open
    response = self._open(req, data)
  File "/usr/local/lib/python3.6/urllib/request.py", line 544, in _open
    '_open', req)
  File "/usr/local/lib/python3.6/urllib/request.py", line 504, in _call_chain
    result = func(*args)
  File "/usr/local/lib/python3.6/urllib/request.py", line 1346, in http_open
    return self.do_open(http.client.HTTPConnection, req)
  File "/usr/local/lib/python3.6/urllib/request.py", line 1320, in do_open
    raise URLError(err)
urllib.error.URLError: <urlopen error [Errno 111] Connection refused>

real	0m1.171s
user	0m1.066s
sys	0m0.102s
