Traceback (most recent call last):
  File "../tasks//python/rest/server.py", line 12, in <module>
    app.run(host='195.251.251.27', port=5000)
  File "/usr/lib64/python2.7/site-packages/flask/app.py", line 943, in run
    run_simple(host, port, self, **options)
  File "/usr/lib/python2.7/site-packages/werkzeug/serving.py", line 814, in run_simple
    inner()
  File "/usr/lib/python2.7/site-packages/werkzeug/serving.py", line 774, in inner
    fd=fd)
  File "/usr/lib/python2.7/site-packages/werkzeug/serving.py", line 660, in make_server
    passthrough_errors, ssl_context, fd=fd)
  File "/usr/lib/python2.7/site-packages/werkzeug/serving.py", line 577, in __init__
    self.address_family), handler)
  File "/usr/lib64/python2.7/SocketServer.py", line 417, in __init__
    self.server_bind()
  File "/usr/lib64/python2.7/BaseHTTPServer.py", line 108, in server_bind
    SocketServer.TCPServer.server_bind(self)
  File "/usr/lib64/python2.7/SocketServer.py", line 431, in server_bind
    self.socket.bind(self.server_address)
  File "/usr/lib64/python2.7/socket.py", line 228, in meth
    return getattr(self._sock,name)(*args)
socket.error: [Errno 98] Address already in use

real	0m0.066s
user	0m0.048s
sys	0m0.018s
